<?xml version="1.0" encoding="utf-8"?>
<!-- This URDF was automatically created by SolidWorks to URDF Exporter! Originally created by Stephen Brawner (brawner@gmail.com) 
     Commit Version: 1.6.0-4-g7f85cfe  Build Version: 1.6.7995.38578
     For more information, please see http://wiki.ros.org/sw_urdf_exporter -->
<robot
  name="RobotArmAssmtry2_KR-URDF">
  <link
    name="base_link">
    <inertial>
      <origin
        xyz="-2.6021E-17 3.9031E-18 0.090482"
        rpy="0 0 0" />
      <mass
        value="200.71" />
      <inertia
        ixx="2.886"
        ixy="-4.8388E-16"
        ixz="9.5025E-17"
        iyy="2.886"
        iyz="2.1016E-16"
        izz="4.6711" />
    </inertial>
    <visual>
      <origin
        xyz="0 0 0"
        rpy="0 0 0" />
      <geometry>
        <mesh
          filename="package://RobotArmAssmtry2_KR-URDF/meshes/base_link.STL" />
      </geometry>
      <material
        name="">
        <color
          rgba="0.64706 0.61961 0.58824 1" />
      </material>
    </visual>
    <collision>
      <origin
        xyz="0 0 0"
        rpy="0 0 0" />
      <geometry>
        <mesh
          filename="package://RobotArmAssmtry2_KR-URDF/meshes/base_link.STL" />
      </geometry>
    </collision>
  </link>
  <link
    name="link_1">
    <inertial>
      <origin
        xyz="-4.3368E-18 2.3636E-17 0.050484"
        rpy="0 0 0" />
      <mass
        value="24.489" />
      <inertia
        ixx="0.20327"
        ixy="-3.8432E-17"
        ixz="-8.3753E-18"
        iyy="0.21043"
        iyz="-3.1918E-17"
        izz="0.15616" />
    </inertial>
    <visual>
      <origin
        xyz="0 0 0"
        rpy="0 0 0" />
      <geometry>
        <mesh
          filename="package://RobotArmAssmtry2_KR-URDF/meshes/link_1.STL" />
      </geometry>
      <material
        name="">
        <color
          rgba="0.64706 0.61961 0.58824 1" />
      </material>
    </visual>
    <collision>
      <origin
        xyz="0 0 0"
        rpy="0 0 0" />
      <geometry>
        <mesh
          filename="package://RobotArmAssmtry2_KR-URDF/meshes/link_1.STL" />
      </geometry>
    </collision>
  </link>
  <joint
    name="joint_1"
    type="revolute">
    <origin
      xyz="0 0 0.24"
      rpy="0 0 0" />
    <parent
      link="base_link" />
    <child
      link="link_1" />
    <axis
      xyz="0 0 1" />
    <limit
      lower="0"
      upper="3.142"
      effort="300"
      velocity="3" />
  </joint>
  <link
    name="link_2">
    <inertial>
      <origin
        xyz="-0.08 9.7361E-17 0.16982"
        rpy="0 0 0" />
      <mass
        value="46.25" />
      <inertia
        ixx="1.0707"
        ixy="-1.748E-18"
        ixz="1.3262E-16"
        iyy="1.0506"
        iyz="-5.8089E-16"
        izz="0.098267" />
    </inertial>
    <visual>
      <origin
        xyz="0 0 0"
        rpy="0 0 0" />
      <geometry>
        <mesh
          filename="package://RobotArmAssmtry2_KR-URDF/meshes/link_2.STL" />
      </geometry>
      <material
        name="">
        <color
          rgba="0.64706 0.61961 0.58824 1" />
      </material>
    </visual>
    <collision>
      <origin
        xyz="0 0 0"
        rpy="0 0 0" />
      <geometry>
        <mesh
          filename="package://RobotArmAssmtry2_KR-URDF/meshes/link_2.STL" />
      </geometry>
    </collision>
  </link>
  <joint
    name="joint_2"
    type="revolute">
    <origin
      xyz="0.08 0 0.145"
      rpy="0 0 0" />
    <parent
      link="link_1" />
    <child
      link="link_2" />
    <axis
      xyz="1 0 0" />
    <limit
      lower="-1.57"
      upper="1.57"
      effort="200"
      velocity="3" />
  </joint>
  <link
    name="link_3">
    <inertial>
      <origin
        xyz="-0.08 -0.17448 -1.6578E-05"
        rpy="0 0 0" />
      <mass
        value="25.215" />
      <inertia
        ixx="0.2383"
        ixy="-1.151E-17"
        ixz="4.4462E-17"
        iyy="0.068002"
        iyz="0.00024059"
        izz="0.27042" />
    </inertial>
    <visual>
      <origin
        xyz="0 0 0"
        rpy="0 0 0" />
      <geometry>
        <mesh
          filename="package://RobotArmAssmtry2_KR-URDF/meshes/link_3.STL" />
      </geometry>
      <material
        name="">
        <color
          rgba="0.64706 0.61961 0.58824 1" />
      </material>
    </visual>
    <collision>
      <origin
        xyz="0 0 0"
        rpy="0 0 0" />
      <geometry>
        <mesh
          filename="package://RobotArmAssmtry2_KR-URDF/meshes/link_3.STL" />
      </geometry>
    </collision>
  </link>
  <joint
    name="joint_3"
    type="revolute">
    <origin
      xyz="0 0 0.4"
      rpy="0 0 0" />
    <parent
      link="link_2" />
    <child
      link="link_3" />
    <axis
      xyz="1 0 0" />
    <limit
      lower="0"
      upper="3.142"
      effort="200"
      velocity="3" />
  </joint>
  <link
    name="link_4">
    <inertial>
      <origin
        xyz="-0.07 0 -0.069541"
        rpy="0 0 0" />
      <mass
        value="15.43" />
      <inertia
        ixx="0.086931"
        ixy="-1.0456E-18"
        ixz="-1.0108E-17"
        iyy="0.088133"
        iyz="-2.1053E-18"
        izz="0.020723" />
    </inertial>
    <visual>
      <origin
        xyz="0 0 0"
        rpy="0 0 0" />
      <geometry>
        <mesh
          filename="package://RobotArmAssmtry2_KR-URDF/meshes/link_4.STL" />
      </geometry>
      <material
        name="">
        <color
          rgba="0.64706 0.61961 0.58824 1" />
      </material>
    </visual>
    <collision>
      <origin
        xyz="0 0 0"
        rpy="0 0 0" />
      <geometry>
        <mesh
          filename="package://RobotArmAssmtry2_KR-URDF/meshes/link_4.STL" />
      </geometry>
    </collision>
  </link>
  <joint
    name="joint_4"
    type="revolute">
    <origin
      xyz="-0.01 -0.35 0"
      rpy="0 0 0" />
    <parent
      link="link_3" />
    <child
      link="link_4" />
    <axis
      xyz="1 0 0" />
    <limit
      lower="0"
      upper="-3.142"
      effort="200"
      velocity="3" />
  </joint>
  <link
    name="link_5">
    <inertial>
      <origin
        xyz="3.0358E-17 -5.5511E-17 -0.0061893"
        rpy="0 0 0" />
      <mass
        value="1.571" />
      <inertia
        ixx="0.0009974"
        ixy="1.6821E-19"
        ixz="5.8059E-19"
        iyy="0.0018704"
        iyz="1.5583E-19"
        izz="0.0024902" />
    </inertial>
    <visual>
      <origin
        xyz="0 0 0"
        rpy="0 0 0" />
      <geometry>
        <mesh
          filename="package://RobotArmAssmtry2_KR-URDF/meshes/link_5.STL" />
      </geometry>
      <material
        name="">
        <color
          rgba="0.64706 0.61961 0.58824 1" />
      </material>
    </visual>
    <collision>
      <origin
        xyz="0 0 0"
        rpy="0 0 0" />
      <geometry>
        <mesh
          filename="package://RobotArmAssmtry2_KR-URDF/meshes/link_5.STL" />
      </geometry>
    </collision>
  </link>
  <joint
    name="joint_5"
    type="revolute">
    <origin
      xyz="-0.07 0 -0.225"
      rpy="0 0 0" />
    <parent
      link="link_4" />
    <child
      link="link_5" />
    <axis
      xyz="0 0 -1" />
    <limit
      lower="0"
      upper="3.142"
      effort="200"
      velocity="3" />
  </joint>
  <link
    name="link_6">
    <inertial>
      <origin
        xyz="0.058814 0.01 -0.020817"
        rpy="0 0 0" />
      <mass
        value="0.94802" />
      <inertia
        ixx="0.00070852"
        ixy="1.5329E-20"
        ixz="8.2588E-05"
        iyy="0.00059395"
        iyz="-1.7275E-20"
        izz="0.0003235" />
    </inertial>
    <visual>
      <origin
        xyz="0 0 0"
        rpy="0 0 0" />
      <geometry>
        <mesh
          filename="package://RobotArmAssmtry2_KR-URDF/meshes/link_6.STL" />
      </geometry>
      <material
        name="">
        <color
          rgba="0.64706 0.61961 0.58824 1" />
      </material>
    </visual>
    <collision>
      <origin
        xyz="0 0 0"
        rpy="0 0 0" />
      <geometry>
        <mesh
          filename="package://RobotArmAssmtry2_KR-URDF/meshes/link_6.STL" />
      </geometry>
    </collision>
  </link>
  <joint
    name="joint_6"
    type="prismatic">
    <origin
      xyz="-0.075 -0.01 -0.03"
      rpy="0 0 0" />
    <parent
      link="link_5" />
    <child
      link="link_6" />
    <axis
      xyz="1 0 0" />
    <limit
      lower="0"
      upper="-0.03"
      effort="100"
      velocity="3" />
  </joint>
  <link
    name="link_7">
    <inertial>
      <origin
        xyz="0.091186 -0.01 -0.020817"
        rpy="0 0 0" />
      <mass
        value="0.94802" />
      <inertia
        ixx="0.00070852"
        ixy="4.2537E-21"
        ixz="-8.2588E-05"
        iyy="0.00059395"
        iyz="4.8911E-21"
        izz="0.0003235" />
    </inertial>
    <visual>
      <origin
        xyz="0 0 0"
        rpy="0 0 0" />
      <geometry>
        <mesh
          filename="package://RobotArmAssmtry2_KR-URDF/meshes/link_7.STL" />
      </geometry>
      <material
        name="">
        <color
          rgba="0.64706 0.61961 0.58824 1" />
      </material>
    </visual>
    <collision>
      <origin
        xyz="0 0 0"
        rpy="0 0 0" />
      <geometry>
        <mesh
          filename="package://RobotArmAssmtry2_KR-URDF/meshes/link_7.STL" />
      </geometry>
    </collision>
  </link>
  <joint
    name="joint_7"
    type="prismatic">
    <origin
      xyz="-0.075 0.01 -0.03"
      rpy="0 0 0" />
    <parent
      link="link_5" />
    <child
      link="link_7" />
    <axis
      xyz="-1 0 0" />
    <limit
      lower="0"
      upper="0.03"
      effort="100"
      velocity="3" />
  </joint>
</robot>